Workbook
Name Fragmentator_Status: #N/A
Name Slicer_Klasa: #N/A

Sheet Lista uczniów_składki
G1: =SUBTOTAL(9,G3:G614) -> 1800 | H1: =SUBTOTAL(9,H3:H614) -> 0 | I1: =SUBTOTAL(9,I3:I614) -> 0 | J1: =SUBTOTAL(9,J3:J614) -> 0 | K1: =SUBTOTAL(9,K3:K614) -> 0 | L1: =SUBTOTAL(9,L3:L614) -> 0 | M1: =SUBTOTAL(9,M3:M614) -> 0 | N1: =SUBTOTAL(9,N3:N614) -> 0 | ... V1: =SUBTOTAL(9,V3:V614) -> -10080
A2: Nazwisko | B2: Imię | C2: Klasa | D2: Czy idzie? | E2: Osoba towarzysząca? | F2: Numer kontaktowy rodzica | G2: 2025 | H2: Sty | I2: Lut | J2: Mar | K2: Kwi | L2: Maj | M2: Cze | N2: Lip | O2: Sie | P2: Wrz | Q2: Paź | R2: Lis | S2: Gru | T2: Razem | U2: Winno byc | V2: Delta | W2: Status | X2: Komentarz
A3: Rząsowska | B3: Daria | C3: 3E | D3: Tak | E3: Tak | G3: 50 | T3: =SUM(G3:S3) -> 50 | U3: =IF(Table2[[#This Row],[Nazwisko]]="","",IF(AND(D3="Nie",E3="Nie"),0,IF(AND(D3="Tak",E3="Nie"),Podsumowanie!$B$19,Podsumowanie!$C$19))) -> 700 | V3: =IFERROR(T3-U3,"") -> -650 | W3: =IF(OR(A3="",V3=0),"",IF(OR(V3>-0.01,V3=0),"OK","NOK")) -> NOK | Z3: =Table2[[#This Row],[Nazwisko]]&Table2[[#This Row],[Imię]] -> RząsowskaDaria | AA3: =COUNTIF(Z3:$Z$275,Z3) -> 1
A4: Szwejda | B4: Martyna | C4: 3E | D4: Tak | E4: Tak | G4: 50 | T4: =SUM(G4:S4) -> 50 | U4: =IF(Table2[[#This Row],[Nazwisko]]="","",IF(AND(D4="Nie",E4="Nie"),0,IF(AND(D4="Tak",E4="Nie"),Podsumowanie!$B$19,Podsumowanie!$C$19))) -> 700 | V4: =IFERROR(T4-U4,"") -> -650 | W4: =IF(OR(A4="",V4=0),"",IF(OR(V4>-0.01,V4=0),"OK","NOK")) -> NOK | Z4: =Table2[[#This Row],[Nazwisko]]&Table2[[#This Row],[Imię]] -> SzwejdaMartyna | AA4: =COUNTIF(Z4:$Z$275,Z4) -> 1
A5: Surosz | B5: Mikołaj | C5: 3D1 | D5: Tak | E5: Nie | G5: 50 | Q5: 200 | T5: =SUM(G5:S5) -> 250 | U5: =IF(Table2[[#This Row],[Nazwisko]]="","",IF(AND(D5="Nie",E5="Nie"),0,IF(AND(D5="Tak",E5="Nie"),Podsumowanie!$B$19,Podsumowanie!$C$19))) -> 430 | V5: =IFERROR(T5-U5,"") -> -180 | W5: =IF(OR(A5="",V5=0),"",IF(OR(V5>-0.01,V5=0),"OK","NOK")) -> NOK | Z5: =Table2[[#This Row],[Nazwisko]]&Table2[[#This Row],[Imię]] -> SuroszMikołaj | AA5: =COUNTIF(Z5:$Z$275,Z5) -> 1
A6: Hofman | B6: Aleksandra | C6: 3E | D6: Tak | E6: Tak | G6: 50 | T6: =SUM(G6:S6) -> 50 | U6: =IF(Table2[[#This Row],[Nazwisko]]="","",IF(AND(D6="Nie",E6="Nie"),0,IF(AND(D6="Tak",E6="Nie"),Podsumowanie!$B$19,Podsumowanie!$C$19))) -> 700 | V6: =IFERROR(T6-U6,"") -> -650 | W6: =IF(OR(A6="",V6=0),"",IF(OR(V6>-0.01,V6=0),"OK","NOK")) -> NOK | Z6: =Table2[[#This Row],[Nazwisko]]&Table2[[#This Row],[Imię]] -> HofmanAleksandra | AA6: =COUNTIF(Z6:$Z$275,Z6) -> 1
A7: Dworak | B7: Patrycja | C7: 3E | D7: Tak | E7: Tak | G7: 50 | T7: =SUM(G7:S7) -> 50 | U7: =IF(Table2[[#This Row],[Nazwisko]]="","",IF(AND(D7="Nie",E7="Nie"),0,IF(AND(D7="Tak",E7="Nie"),Podsumowanie!$B$19,Podsumowanie!$C$19))) -> 700 | V7: =IFERROR(T7-U7,"") -> -650 | W7: =IF(OR(A7="",V7=0),"",IF(OR(V7>-0.01,V7=0),"OK","NOK")) -> NOK | Z7: =Table2[[#This Row],[Nazwisko]]&Table2[[#This Row],[Imię]] -> DworakPatrycja | AA7: =COUNTIF(Z7:$Z$275,Z7) -> 1
A8: Krzyszkowska | B8: Lena | C8: 3D1 | D8: Tak | E8: Tak | G8: 50 | Q8: 200 | T8: =SUM(G8:S8) -> 250 | U8: =IF(Table2[[#This Row],[Nazwisko]]="","",IF(AND(D8="Nie",E8="Nie"),0,IF(AND(D8="Tak",E8="Nie"),Podsumowanie!$B$19,Podsumowanie!$C$19))) -> 700 | V8: =IFERROR(T8-U8,"") -> -450 | W8: =IF(OR(A8="",V8=0),"",IF(OR(V8>-0.01,V8=0),"OK","NOK")) -> NOK | Z8: =Table2[[#This Row],[Nazwisko]]&Table2[[#This Row],[Imię]] -> KrzyszkowskaLena | AA8: =COUNTIF(Z8:$Z$275,Z8) -> 1
A9: Alama | B9: Aleksandra | C9: 3E | D9: Tak | E9: Tak | G9: 50 | T9: =SUM(G9:S9) -> 50 | U9: =IF(Table2[[#This Row],[Nazwisko]]="","",IF(AND(D9="Nie",E9="Nie"),0,IF(AND(D9="Tak",E9="Nie"),Podsumowanie!$B$19,Podsumowanie!$C$19))) -> 700 | V9: =IFERROR(T9-U9,"") -> -650 | W9: =IF(OR(A9="",V9=0),"",IF(OR(V9>-0.01,V9=0),"OK","NOK")) -> NOK | Z9: =Table2[[#This Row],[Nazwisko]]&Table2[[#This Row],[Imię]] -> AlamaAleksandra | AA9: =COUNTIF(Z9:$Z$275,Z9) -> 1
A10: Półrola | B10: Alan | C10: 3D1 | D10: Tak | E10: Nie | G10: 50 | Q10: 200 | T10: =SUM(G10:S10) -> 250 | U10: =IF(Table2[[#This Row],[Nazwisko]]="","",IF(AND(D10="Nie",E10="Nie"),0,IF(AND(D10="Tak",E10="Nie"),Podsumowanie!$B$19,Podsumowanie!$C$19))) -> 430 | V10: =IFERROR(T10-U10,"") -> -180 | W10: =IF(OR(A10="",V10=0),"",IF(OR(V10>-0.01,V10=0),"OK","NOK")) -> NOK | Z10: =Table2[[#This Row],[Nazwisko]]&Table2[[#This Row],[Imię]] -> PółrolaAlan | AA10: =COUNTIF(Z10:$Z$275,Z10) -> 1
A11: Berski | B11: Jakub | C11: 3D1 | D11: Tak | E11: Tak | G11: 50 | Q11: 200 | T11: =SUM(G11:S11) -> 250 | U11: =IF(Table2[[#This Row],[Nazwisko]]="","",IF(AND(D11="Nie",E11="Nie"),0,IF(AND(D11="Tak",E11="Nie"),Podsumowanie!$B$19,Podsumowanie!$C$19))) -> 700 | V11: =IFERROR(T11-U11,"") -> -450 | W11: =IF(OR(A11="",V11=0),"",IF(OR(V11>-0.01,V11=0),"OK","NOK")) -> NOK | Z11: =Table2[[#This Row],[Nazwisko]]&Table2[[#This Row],[Imię]] -> BerskiJakub | AA11: =COUNTIF(Z11:$Z$275,Z11) -> 1
A12: Ciupa | B12: Weronika | C12: 3E | D12: Tak | E12: Tak | G12: 50 | T12: =SUM(G12:S12) -> 50 | U12: =IF(Table2[[#This Row],[Nazwisko]]="","",IF(AND(D12="Nie",E12="Nie"),0,IF(AND(D12="Tak",E12="Nie"),Podsumowanie!$B$19,Podsumowanie!$C$19))) -> 700 | V12: =IFERROR(T12-U12,"") -> -650 | W12: =IF(OR(A12="",V12=0),"",IF(OR(V12>-0.01,V12=0),"OK","NOK")) -> NOK | Z12: =Table2[[#This Row],[Nazwisko]]&Table2[[#This Row],[Imię]] -> CiupaWeronika | AA12: =COUNTIF(Z12:$Z$275,Z12) -> 1
A13: Zawalska | B13: Zofia | C13: 3D1 | D13: Tak | E13: Nie | G13: 50 | Q13: 200 | T13: =SUM(G13:S13) -> 250 | U13: =IF(Table2[[#This Row],[Nazwisko]]="","",IF(AND(D13="Nie",E13="Nie"),0,IF(AND(D13="Tak",E13="Nie"),Podsumowanie!$B$19,Podsumowanie!$C$19))) -> 430 | V13: =IFERROR(T13-U13,"") -> -180 | W13: =IF(OR(A13="",V13=0),"",IF(OR(V13>-0.01,V13=0),"OK","NOK")) -> NOK | Z13: =Table2[[#This Row],[Nazwisko]]&Table2[[#This Row],[Imię]] -> ZawalskaZofia | AA13: =COUNTIF(Z13:$Z$275,Z13) -> 1
A14: Rosik | B14: Roksana | C14: 3E | D14: Tak | E14: Tak | G14: 50 | T14: =SUM(G14:S14) -> 50 | U14: =IF(Table2[[#This Row],[Nazwisko]]="","",IF(AND(D14="Nie",E14="Nie"),0,IF(AND(D14="Tak",E14="Nie"),Podsumowanie!$B$19,Podsumowanie!$C$19))) -> 700 | V14: =IFERROR(T14-U14,"") -> -650 | W14: =IF(OR(A14="",V14=0),"",IF(OR(V14>-0.01,V14=0),"OK","NOK")) -> NOK | Z14: =Table2[[#This Row],[Nazwisko]]&Table2[[#This Row],[Imię]] -> RosikRoksana | AA14: =COUNTIF(Z14:$Z$275,Z14) -> 1
A15: Warda | B15: Wiktoria | C15: 3B | D15: Tak | E15: Tak | G15: 50 | Q15: 200 | T15: =SUM(G15:S15) -> 250 | U15: =IF(Table2[[#This Row],[Nazwisko]]="","",IF(AND(D15="Nie",E15="Nie"),0,IF(AND(D15="Tak",E15="Nie"),Podsumowanie!$B$19,Podsumowanie!$C$19))) -> 700 | V15: =IFERROR(T15-U15,"") -> -450 | W15: =IF(OR(A15="",V15=0),"",IF(OR(V15>-0.01,V15=0),"OK","NOK")) -> NOK | Z15: =Table2[[#This Row],[Nazwisko]]&Table2[[#This Row],[Imię]] -> WardaWiktoria | AA15: =COUNTIF(Z15:$Z$275,Z15) -> 1
A16: Kozłowski | B16: Seweryn | C16: 3B | D16: Tak | E16: Tak | G16: 50 | Q16: 300 | T16: =SUM(G16:S16) -> 350 | U16: =IF(Table2[[#This Row],[Nazwisko]]="","",IF(AND(D16="Nie",E16="Nie"),0,IF(AND(D16="Tak",E16="Nie"),Podsumowanie!$B$19,Podsumowanie!$C$19))) -> 700 | V16: =IFERROR(T16-U16,"") -> -350 | W16: =IF(OR(A16="",V16=0),"",IF(OR(V16>-0.01,V16=0),"OK","NOK")) -> NOK | Z16: =Table2[[#This Row],[Nazwisko]]&Table2[[#This Row],[Imię]] -> KozłowskiSeweryn | AA16: =COUNTIF(Z16:$Z$275,Z16) -> 1
A17: Nita | B17: Oliwia | C17: 3D1 | D17: Tak | E17: Nie | G17: 50 | Q17: 200 | T17: =SUM(G17:S17) -> 250 | U17: =IF(Table2[[#This Row],[Nazwisko]]="","",IF(AND(D17="Nie",E17="Nie"),0,IF(AND(D17="Tak",E17="Nie"),Podsumowanie!$B$19,Podsumowanie!$C$19))) -> 430 | V17: =IFERROR(T17-U17,"") -> -180 | W17: =IF(OR(A17="",V17=0),"",IF(OR(V17>-0.01,V17=0),"OK","NOK")) -> NOK | Z17: =Table2[[#This Row],[Nazwisko]]&Table2[[#This Row],[Imię]] -> NitaOliwia | AA17: =COUNTIF(Z17:$Z$275,Z17) -> 1
A18: Bergier | B18: Natalia | C18: 3B | D18: Tak | E18: Nie | G18: 50 | Q18: 100 | T18: =SUM(G18:S18) -> 150 | U18: =IF(Table2[[#This Row],[Nazwisko]]="","",IF(AND(D18="Nie",E18="Nie"),0,IF(AND(D18="Tak",E18="Nie"),Podsumowanie!$B$19,Podsumowanie!$C$19))) -> 430 | V18: =IFERROR(T18-U18,"") -> -280 | W18: =IF(OR(A18="",V18=0),"",IF(OR(V18>-0.01,V18=0),"OK","NOK")) -> NOK | Z18: =Table2[[#This Row],[Nazwisko]]&Table2[[#This Row],[Imię]] -> BergierNatalia | AA18: =COUNTIF(Z18:$Z$275,Z18) -> 1
A19: Janusz | B19: Magda | C19: 3B | D19: Tak | E19: Tak | G19: 50 | Q19: 200 | T19: =SUM(G19:S19) -> 250 | U19: =IF(Table2[[#This Row],[Nazwisko]]="","",IF(AND(D19="Nie",E19="Nie"),0,IF(AND(D19="Tak",E19="Nie"),Podsumowanie!$B$19,Podsumowanie!$C$19))) -> 700 | V19: =IFERROR(T19-U19,"") -> -450 | W19: =IF(OR(A19="",V19=0),"",IF(OR(V19>-0.01,V19=0),"OK","NOK")) -> NOK | Z19: =Table2[[#This Row],[Nazwisko]]&Table2[[#This Row],[Imię]] -> JanuszMagda | AA19: =COUNTIF(Z19:$Z$275,Z19) -> 1
A20: Raczyńska | B20: Maja | C20: 3B | D20: Tak | E20: Tak | G20: 50 | Q20: 100 | T20: =SUM(G20:S20) -> 150 | U20: =IF(Table2[[#This Row],[Nazwisko]]="","",IF(AND(D20="Nie",E20="Nie"),0,IF(AND(D20="Tak",E20="Nie"),Podsumowanie!$B$19,Podsumowanie!$C$19))) -> 700 | V20: =IFERROR(T20-U20,"") -> -550 | W20: =IF(OR(A20="",V20=0),"",IF(OR(V20>-0.01,V20=0),"OK","NOK")) -> NOK | Z20: =Table2[[#This Row],[Nazwisko]]&Table2[[#This Row],[Imię]] -> RaczyńskaMaja | AA20: =COUNTIF(Z20:$Z$275,Z20) -> 1
A21: Mordak | B21: Nikola | C21: 3B | D21: Tak | E21: Nie | G21: 50 | T21: =SUM(G21:S21) -> 50 | U21: =IF(Table2[[#This Row],[Nazwisko]]="","",IF(AND(D21="Nie",E21="Nie"),0,IF(AND(D21="Tak",E21="Nie"),Podsumowanie!$B$19,Podsumowanie!$C$19))) -> 430 | V21: =IFERROR(T21-U21,"") -> -380 | W21: =IF(OR(A21="",V21=0),"",IF(OR(V21>-0.01,V21=0),"OK","NOK")) -> NOK | Z21: =Table2[[#This Row],[Nazwisko]]&Table2[[#This Row],[Imię]] -> MordakNikola | AA21: =COUNTIF(Z21:$Z$275,Z21) -> 1
A22: Barnaś | B22: Iga | C22: 3B | D22: Tak | E22: Tak | G22: 50 | Q22: 100 | T22: =SUM(G22:S22) -> 150 | U22: =IF(Table2[[#This Row],[Nazwisko]]="","",IF(AND(D22="Nie",E22="Nie"),0,IF(AND(D22="Tak",E22="Nie"),Podsumowanie!$B$19,Podsumowanie!$C$19))) -> 700 | V22: =IFERROR(T22-U22,"") -> -550 | W22: =IF(OR(A22="",V22=0),"",IF(OR(V22>-0.01,V22=0),"OK","NOK")) -> NOK | Z22: =Table2[[#This Row],[Nazwisko]]&Table2[[#This Row],[Imię]] -> BarnaśIga | AA22: =COUNTIF(Z22:$Z$275,Z22) -> 1
A23: Palka | B23: Daria | C23: 3B | D23: Tak | E23: Tak | G23: 50 | Q23: 100 | T23: =SUM(G23:S23) -> 150 | U23: =IF(Table2[[#This Row],[Nazwisko]]="","",IF(AND(D23="Nie",E23="Nie"),0,IF(AND(D23="Tak",E23="Nie"),Podsumowanie!$B$19,Podsumowanie!$C$19))) -> 700 | V23: =IFERROR(T23-U23,"") -> -550 | W23: =IF(OR(A23="",V23=0),"",IF(OR(V23>-0.01,V23=0),"OK","NOK")) -> NOK | Z23: =Table2[[#This Row],[Nazwisko]]&Table2[[#This Row],[Imię]] -> PalkaDaria | AA23: =COUNTIF(Z23:$Z$275,Z23) -> 1
A24: Proszowska | B24: Katarzyna | C24: 3D1 | D24: Tak | E24: Tak | G24: 50 | Q24: 200 | T24: =SUM(G24:S24) -> 250 | U24: =IF(Table2[[#This Row],[Nazwisko]]="","",IF(AND(D24="Nie",E24="Nie"),0,IF(AND(D24="Tak",E24="Nie"),Podsumowanie!$B$19,Podsumowanie!$C$19))) -> 700 | V24: =IFERROR(T24-U24,"") -> -450 | W24: =IF(OR(A24="",V24=0),"",IF(OR(V24>-0.01,V24=0),"OK","NOK")) -> NOK | Z24: =Table2[[#This Row],[Nazwisko]]&Table2[[#This Row],[Imię]] -> ProszowskaKatarzyna | AA24: =COUNTIF(Z24:$Z$275,Z24) -> 1
A25: Pietruszyńska | B25: Maja | C25: 3B | D25: Tak | E25: Tak | G25: 50 | Q25: 400 | T25: =SUM(G25:S25) -> 450 | U25: =IF(Table2[[#This Row],[Nazwisko]]="","",IF(AND(D25="Nie",E25="Nie"),0,IF(AND(D25="Tak",E25="Nie"),Podsumowanie!$B$19,Podsumowanie!$C$19))) -> 700 | V25: =IFERROR(T25-U25,"") -> -250 | W25: =IF(OR(A25="",V25=0),"",IF(OR(V25>-0.01,V25=0),"OK","NOK")) -> NOK | Z25: =Table2[[#This Row],[Nazwisko]]&Table2[[#This Row],[Imię]] -> PietruszyńskaMaja | AA25: =COUNTIF(Z25:$Z$275,Z25) -> 1
A26: Winkler | B26: Julia | C26: 3D1 | D26: Tak | E26: Nie | G26: 50 | Q26: 200 | T26: =SUM(G26:S26) -> 250 | U26: =IF(Table2[[#This Row],[Nazwisko]]="","",IF(AND(D26="Nie",E26="Nie"),0,IF(AND(D26="Tak",E26="Nie"),Podsumowanie!$B$19,Podsumowanie!$C$19))) -> 430 | V26: =IFERROR(T26-U26,"") -> -180 | W26: =IF(OR(A26="",V26=0),"",IF(OR(V26>-0.01,V26=0),"OK","NOK")) -> NOK | Z26: =Table2[[#This Row],[Nazwisko]]&Table2[[#This Row],[Imię]] -> WinklerJulia | AA26: =COUNTIF(Z26:$Z$275,Z26) -> 1
A27: Guszkiewicz | B27: Maja | C27: 3D1 | D27: Tak | E27: Tak | G27: 50 | Q27: 650 | T27: =SUM(G27:S27) -> 700 | U27: =IF(Table2[[#This Row],[Nazwisko]]="","",IF(AND(D27="Nie",E27="Nie"),0,IF(AND(D27="Tak",E27="Nie"),Podsumowanie!$B$19,Podsumowanie!$C$19))) -> 700 | V27: =IFERROR(T27-U27,"") -> 0 | W27: =IF(OR(A27="",V27=0),"",IF(OR(V27>-0.01,V27=0),"OK","NOK")) | Z27: =Table2[[#This Row],[Nazwisko]]&Table2[[#This Row],[Imię]] -> GuszkiewiczMaja | AA27: =COUNTIF(Z27:$Z$275,Z27) -> 1
A28: Buliński | B28: Maciej | C28: 3D1 | D28: Tak | E28: Nie | G28: 50 | Q28: 200 | T28: =SUM(G28:S28) -> 250 | U28: =IF(Table2[[#This Row],[Nazwisko]]="","",IF(AND(D28="Nie",E28="Nie"),0,IF(AND(D28="Tak",E28="Nie"),Podsumowanie!$B$19,Podsumowanie!$C$19))) -> 430 | V28: =IFERROR(T28-U28,"") -> -180 | W28: =IF(OR(A28="",V28=0),"",IF(OR(V28>-0.01,V28=0),"OK","NOK")) -> NOK | Z28: =Table2[[#This Row],[Nazwisko]]&Table2[[#This Row],[Imię]] -> BulińskiMaciej | AA28: =COUNTIF(Z28:$Z$275,Z28) -> 1
A29: Pietras | B29: Zuzanna | C29: 3D1 | D29: Tak | E29: Nie | G29: 50 | Q29: 200 | T29: =SUM(G29:S29) -> 250 | U29: =IF(Table2[[#This Row],[Nazwisko]]="","",IF(AND(D29="Nie",E29="Nie"),0,IF(AND(D29="Tak",E29="Nie"),Podsumowanie!$B$19,Podsumowanie!$C$19))) -> 430 | V29: =IFERROR(T29-U29,"") -> -180 | W29: =IF(OR(A29="",V29=0),"",IF(OR(V29>-0.01,V29=0),"OK","NOK")) -> NOK | Z29: =Table2[[#This Row],[Nazwisko]]&Table2[[#This Row],[Imię]] -> PietrasZuzanna | AA29: =COUNTIF(Z29:$Z$275,Z29) -> 1
A30: Sitek | B30: Szymon | C30: 3D1 | D30: Tak | E30: Tak | G30: 50 | Q30: 200 | T30: =SUM(G30:S30) -> 250 | U30: =IF(Table2[[#This Row],[Nazwisko]]="","",IF(AND(D30="Nie",E30="Nie"),0,IF(AND(D30="Tak",E30="Nie"),Podsumowanie!$B$19,Podsumowanie!$C$19))) -> 700 | V30: =IFERROR(T30-U30,"") -> -450 | W30: =IF(OR(A30="",V30=0),"",IF(OR(V30>-0.01,V30=0),"OK","NOK")) -> NOK | Z30: =Table2[[#This Row],[Nazwisko]]&Table2[[#This Row],[Imię]] -> SitekSzymon | AA30: =COUNTIF(Z30:$Z$275,Z30) -> 1
A31: Wałachowska | B31: Nikola | C31: 3B | D31: Tak | E31: Nie | G31: 50 | Q31: 100 | T31: =SUM(G31:S31) -> 150 | U31: =IF(Table2[[#This Row],[Nazwisko]]="","",IF(AND(D31="Nie",E31="Nie"),0,IF(AND(D31="Tak",E31="Nie"),Podsumowanie!$B$19,Podsumowanie!$C$19))) -> 430 | V31: =IFERROR(T31-U31,"") -> -280 | W31: =IF(OR(A31="",V31=0),"",IF(OR(V31>-0.01,V31=0),"OK","NOK")) -> NOK | Z31: =Table2[[#This Row],[Nazwisko]]&Table2[[#This Row],[Imię]] -> WałachowskaNikola | AA31: =COUNTIF(Z31:$Z$275,Z31) -> 1
A32: Czubaj | B32: Paulina | C32: 3B | D32: Tak | E32: Tak | G32: 50 | Q32: 200 | T32: =SUM(G32:S32) -> 250 | U32: =IF(Table2[[#This Row],[Nazwisko]]="","",IF(AND(D32="Nie",E32="Nie"),0,IF(AND(D32="Tak",E32="Nie"),Podsumowanie!$B$19,Podsumowanie!$C$19))) -> 700 | V32: =IFERROR(T32-U32,"") -> -450 | W32: =IF(OR(A32="",V32=0),"",IF(OR(V32>-0.01,V32=0),"OK","NOK")) -> NOK | Z32: =Table2[[#This Row],[Nazwisko]]&Table2[[#This Row],[Imię]] -> CzubajPaulina | AA32: =COUNTIF(Z32:$Z$275,Z32) -> 1
A33: Błachowicz | B33: Pola | C33: 3B | D33: Tak | E33: Tak | G33: 50 | Q33: 200 | T33: =SUM(G33:S33) -> 250 | U33: =IF(Table2[[#This Row],[Nazwisko]]="","",IF(AND(D33="Nie",E33="Nie"),0,IF(AND(D33="Tak",E33="Nie"),Podsumowanie!$B$19,Podsumowanie!$C$19))) -> 700 | V33: =IFERROR(T33-U33,"") -> -450 | W33: =IF(OR(A33="",V33=0),"",IF(OR(V33>-0.01,V33=0),"OK","NOK")) -> NOK | Z33: =Table2[[#This Row],[Nazwisko]]&Table2[[#This Row],[Imię]] -> BłachowiczPola | AA33: =COUNTIF(Z33:$Z$275,Z33) -> 1
A34: Kowalczyk | B34: Julia | C34: 3C | D34: Tak | E34: Tak | G34: 50 | P34: 100 | Q34: 200 | T34: =SUM(G34:S34) -> 350 | U34: =IF(Table2[[#This Row],[Nazwisko]]="","",IF(AND(D34="Nie",E34="Nie"),0,IF(AND(D34="Tak",E34="Nie"),Podsumowanie!$B$19,Podsumowanie!$C$19))) -> 700 | V34: =IFERROR(T34-U34,"") -> -350 | W34: =IF(OR(A34="",V34=0),"",IF(OR(V34>-0.01,V34=0),"OK","NOK")) -> NOK | Z34: =Table2[[#This Row],[Nazwisko]]&Table2[[#This Row],[Imię]] -> KowalczykJulia | AA34: =COUNTIF(Z34:$Z$275,Z34) -> 2
A35: Zatoń | B35: Olga | C35: 3C | D35: Tak | E35: Tak | G35: 50 | P35: 100 | Q35: 200 | T35: =SUM(G35:S35) -> 350 | U35: =IF(Table2[[#This Row],[Nazwisko]]="","",IF(AND(D35="Nie",E35="Nie"),0,IF(AND(D35="Tak",E35="Nie"),Podsumowanie!$B$19,Podsumowanie!$C$19))) -> 700 | V35: =IFERROR(T35-U35,"") -> -350 | W35: =IF(OR(A35="",V35=0),"",IF(OR(V35>-0.01,V35=0),"OK","NOK")) -> NOK | Z35: =Table2[[#This Row],[Nazwisko]]&Table2[[#This Row],[Imię]] -> ZatońOlga | AA35: =COUNTIF(Z35:$Z$275,Z35) -> 1
A36: Oleszczak | B36: Olga | C36: 3C | D36: Tak | E36: Tak | G36: 50 | P36: 100 | Q36: 200 | T36: =SUM(G36:S36) -> 350 | U36: =IF(Table2[[#This Row],[Nazwisko]]="","",IF(AND(D36="Nie",E36="Nie"),0,IF(AND(D36="Tak",E36="Nie"),Podsumowanie!$B$19,Podsumowanie!$C$19))) -> 700 | V36: =IFERROR(T36-U36,"") -> -350 | W36: =IF(OR(A36="",V36=0),"",IF(OR(V36>-0.01,V36=0),"OK","NOK")) -> NOK | Z36: =Table2[[#This Row],[Nazwisko]]&Table2[[#This Row],[Imię]] -> OleszczakOlga | AA36: =COUNTIF(Z36:$Z$275,Z36) -> 1
A37: Włodarczyk | B37: Karolina | C37: 3C | D37: Tak | E37: Nie | G37: 50 | P37: 100 | Q37: 100 | T37: =SUM(G37:S37) -> 250 | U37: =IF(Table2[[#This Row],[Nazwisko]]="","",IF(AND(D37="Nie",E37="Nie"),0,IF(AND(D37="Tak",E37="Nie"),Podsumowanie!$B$19,Podsumowanie!$C$19))) -> 430 | V37: =IFERROR(T37-U37,"") -> -180 | W37: =IF(OR(A37="",V37=0),"",IF(OR(V37>-0.01,V37=0),"OK","NOK")) -> NOK | Z37: =Table2[[#This Row],[Nazwisko]]&Table2[[#This Row],[Imię]] -> WłodarczykKarolina | AA37: =COUNTIF(Z37:$Z$275,Z37) -> 1
A38: Staniszewska | B38: Iga | C38: 3C | D38: Tak | E38: Tak | G38: 50 | P38: 100 | Q38: 100 | T38: =SUM(G38:S38) -> 250 | U38: =IF(Table2[[#This Row],[Nazwisko]]="","",IF(AND(D38="Nie",E38="Nie"),0,IF(AND(D38="Tak",E38="Nie"),Podsumowanie!$B$19,Podsumowanie!$C$19))) -> 700 | V38: =IFERROR(T38-U38,"") -> -450 | W38: =IF(OR(A38="",V38=0),"",IF(OR(V38>-0.01,V38=0),"OK","NOK")) -> NOK | Z38: =Table2[[#This Row],[Nazwisko]]&Table2[[#This Row],[Imię]] -> StaniszewskaIga | AA38: =COUNTIF(Z38:$Z$275,Z38) -> 1
A39: Wyczółkowska | B39: Milena | C39: 3C | D39: Tak | E39: Tak | G39: 50 | P39: 100 | Q39: 200 | T39: =SUM(G39:S39) -> 350 | U39: =IF(Table2[[#This Row],[Nazwisko]]="","",IF(AND(D39="Nie",E39="Nie"),0,IF(AND(D39="Tak",E39="Nie"),Podsumowanie!$B$19,Podsumowanie!$C$19))) -> 700 | V39: =IFERROR(T39-U39,"") -> -350 | W39: =IF(OR(A39="",V39=0),"",IF(OR(V39>-0.01,V39=0),"OK","NOK")) -> NOK | Z39: =Table2[[#This Row],[Nazwisko]]&Table2[[#This Row],[Imię]] -> WyczółkowskaMilena | AA39: =COUNTIF(Z39:$Z$275,Z39) -> 1
A40: Kaźmierska | B40: Julia | C40: 3C | D40: Tak | E40: Tak | G40: 50 | P40: 100 | Q40: 200 | T40: =SUM(G40:S40) -> 350 | U40: =IF(Table2[[#This Row],[Nazwisko]]="","",IF(AND(D40="Nie",E40="Nie"),0,IF(AND(D40="Tak",E40="Nie"),Podsumowanie!$B$19,Podsumowanie!$C$19))) -> 700 | V40: =IFERROR(T40-U40,"") -> -350 | W40: =IF(OR(A40="",V40=0),"",IF(OR(V40>-0.01,V40=0),"OK","NOK")) -> NOK | Z40: =Table2[[#This Row],[Nazwisko]]&Table2[[#This Row],[Imię]] -> KaźmierskaJulia | AA40: =COUNTIF(Z40:$Z$275,Z40) -> 1
...

Sheet Sheet1
B4: Bałut | C4: Piotr
B5: Bartnik | C5: Adrianna
B6: Berski | C6: Jakub
B7: Borowski | C7: Antoni
B8: Buliński | C8: Maciej
B9: Cyniak | C9: Mikołaj
B10: Dobosz | C10: Maria
B11: Doroziński | C11: Bartosz
B12: Gębicz | C12: Anna
B13: Grządziel | C13: Patryk
B14: Gurazda | C14: Mikołaj
B15: Guszkiewicz | C15: Maja
... B39: Zawalska | C39: Zofia

Sheet Wydatki
A2: Opis | B2: Umowa done? | C2: Zaliczka done? | D2: Ilość | E2: Cena | F2: Koszt | G2: Zaliczka | H2: Pozostało | I2: Komentarz
A3: Sala uczniowie(PortoFine) | B3: TRUE | C3: TRUE | D3: =Podsumowanie!C12 -> 363 | E3: 270 | F3: =Table1[[#This Row],[Ilość]]*Table1[[#This Row],[Cena]] -> 98010 | G3: 2000 | H3: =Table1[[#This Row],[Koszt]]-Table1[[#This Row],[Zaliczka]] -> 96010 | I3: Zaliczka Michał Krzyszkowski
A4: Goście/pedagodzy/obsługa (PortoFine_na każde 100 osoób 10 jest za darmo na sali) | B4: TRUE | C4: TRUE | D4: 30 | E4: 0 | F4: =Table1[[#This Row],[Ilość]]*Table1[[#This Row],[Cena]] -> 0 | H4: =Table1[[#This Row],[Koszt]]-Table1[[#This Row],[Zaliczka]] -> 0
A5: DJ (Best Party Grupa Eventowa) | B5: TRUE | C5: TRUE | D5: 1 | E5: 8000 | F5: =Table1[[#This Row],[Ilość]]*Table1[[#This Row],[Cena]] -> 8000 | G5: 400 | H5: =Table1[[#This Row],[Koszt]]-Table1[[#This Row],[Zaliczka]] -> 7600 | I5: Zaliczka Aneta Kanafa
A6: Fotograf(FVB) | B6: TRUE | C6: TRUE | D6: 1 | E6: 12000 | F6: =Table1[[#This Row],[Ilość]]*Table1[[#This Row],[Cena]] -> 12000 | G6: 2000 | H6: =Table1[[#This Row],[Koszt]]-Table1[[#This Row],[Zaliczka]] -> 10000 | I6: Zaliczka Michał Krzyszkowski
A7: Ścianka(Anna Muskała) | B7: TRUE | C7: TRUE | D7: 1 | E7: 1400 | F7: =Table1[[#This Row],[Ilość]]*Table1[[#This Row],[Cena]] -> 1400 | G7: 100 | H7: =Table1[[#This Row],[Koszt]]-Table1[[#This Row],[Zaliczka]] -> 1300 | I7: Zaliczka Aneta Kanafa
A8: Opieka karetki | B8: FALSE | D8: 1 | E8: 2000 | F8: =Table1[[#This Row],[Ilość]]*Table1[[#This Row],[Cena]] -> 2000 | H8: =Table1[[#This Row],[Koszt]]-Table1[[#This Row],[Zaliczka]] -> 2000
A9: Ubezpieczenie | B9: FALSE | D9: 1 | E9: 300 | F9: =Table1[[#This Row],[Ilość]]*Table1[[#This Row],[Cena]] -> 300 | H9: =Table1[[#This Row],[Koszt]]-Table1[[#This Row],[Zaliczka]] -> 300
A10: Napoje gazowane [l] ->1,1l/os | B10: FALSE | D10: =(D3+D4)*1.1 -> 432.3 | E10: 7.5 | F10: =Table1[[#This Row],[Ilość]]*Table1[[#This Row],[Cena]] -> 3242.25 | H10: =Table1[[#This Row],[Koszt]]-Table1[[#This Row],[Zaliczka]] -> 3242.25
A11: Kwiaty dla Nauczycieli | B11: FALSE | D11: 7 | E11: 120 | F11: =Table1[[#This Row],[Ilość]]*Table1[[#This Row],[Cena]] -> 840 | H11: =Table1[[#This Row],[Koszt]]-Table1[[#This Row],[Zaliczka]] -> 840
A12: Polonez_nauka [h] (Verto) | B12: TRUE | C12: TRUE | D12: 10 | E12: 180 | F12: =Table1[[#This Row],[Ilość]]*Table1[[#This Row],[Cena]] -> 1800 | G12: 180 | H12: =Table1[[#This Row],[Koszt]]-Table1[[#This Row],[Zaliczka]] -> 1620 | I12: Zaliczka Aneta Kanafa
A13: Koszty dodatkowe | B13: FALSE | C13: FALSE | D13: =Podsumowanie!B12 -> 222 | E13: 10 | F13: =Table1[[#This Row],[Ilość]]*Table1[[#This Row],[Cena]] -> 2220 | G13: 75.85 | H13: =Table1[[#This Row],[Koszt]]-Table1[[#This Row],[Zaliczka]] -> 2144.15 | I13: zakup Kasetki na pieniądze 75.85 (zapłacone)-> Zaiks i inne 1100 zł(do opłacenia)
A14: Total | F14: =SUBTOTAL(109,F3:F13) -> 129812.25 | G14: =SUBTOTAL(109,G3:G13) -> 4755.85 | H14: =SUBTOTAL(109,H3:H13) -> 125056.4

Sheet Podsumowanie
A1: KLASA | B1: # UCZNIÓW (którzy idą) | C1: # OS. Tow. | D1: Total Klasa | E1: Ilość uczniów w klasie | F1: % ankiety | G1: brakuje | H1: ilość odpowiedzi | J1: Składki_winno być | K1: Składki zebrane | L1: Delta
A2: 3A | B2: =COUNTIFS('Lista uczniów_składki'!D:D,"Tak",'Lista uczniów_składki'!C:C,Podsumowanie!A2) -> 33 | C2: =COUNTIFS('Lista uczniów_składki'!E:E,"Tak",'Lista uczniów_składki'!C:C,Podsumowanie!A2) -> 29 | D2: =SUM(B2:C2) -> 62 | E2: 35 | F2: =IF(E2="","",H2/E2) -> 1 | G2: =H2-E2 -> 0 | H2: =COUNTIFS('Lista uczniów_składki'!D:D,"Tak",'Lista uczniów_składki'!C:C,Podsumowanie!A2)+COUNTIFS('Lista uczniów_składki'!D:D,"Nie",'Lista uczniów_składki'!C:C,Podsumowanie!A2) -> 35 | J2: =SUMIFS('Lista uczniów_składki'!U:U,'Lista uczniów_składki'!C:C,Podsumowanie!A2) -> 22020 | K2: =SUMIFS('Lista uczniów_składki'!T:T,'Lista uczniów_składki'!C:C,Podsumowanie!A2) -> 7350 | L2: =K2-J2 -> -14670
A3: 3B | B3: =COUNTIFS('Lista uczniów_składki'!D:D,"Tak",'Lista uczniów_składki'!C:C,Podsumowanie!A3) -> 24 | C3: =COUNTIFS('Lista uczniów_składki'!E:E,"Tak",'Lista uczniów_składki'!C:C,Podsumowanie!A3) -> 16 | D3: =SUM(B3:C3) -> 40 | E3: 25 | F3: =IF(E3="","",H3/E3) -> 1 | G3: =H3-E3 -> 0 | H3: =COUNTIFS('Lista uczniów_składki'!D:D,"Tak",'Lista uczniów_składki'!C:C,Podsumowanie!A3)+COUNTIFS('Lista uczniów_składki'!D:D,"Nie",'Lista uczniów_składki'!C:C,Podsumowanie!A3) -> 25 | J3: =SUMIFS('Lista uczniów_składki'!U:U,'Lista uczniów_składki'!C:C,Podsumowanie!A3) -> 14640 | K3: =SUMIFS('Lista uczniów_składki'!T:T,'Lista uczniów_składki'!C:C,Podsumowanie!A3) -> 5300 | L3: =K3-J3 -> -9340
A4: 3C | B4: =COUNTIFS('Lista uczniów_składki'!D:D,"Tak",'Lista uczniów_składki'!C:C,Podsumowanie!A4) -> 35 | C4: =COUNTIFS('Lista uczniów_składki'!E:E,"Tak",'Lista uczniów_składki'!C:C,Podsumowanie!A4) -> 19 | D4: =SUM(B4:C4) -> 54 | E4: 36 | F4: =IF(E4="","",H4/E4) -> 1 | G4: =H4-E4 -> 0 | H4: =COUNTIFS('Lista uczniów_składki'!D:D,"Tak",'Lista uczniów_składki'!C:C,Podsumowanie!A4)+COUNTIFS('Lista uczniów_składki'!D:D,"Nie",'Lista uczniów_składki'!C:C,Podsumowanie!A4) -> 36 | J4: =SUMIFS('Lista uczniów_składki'!U:U,'Lista uczniów_składki'!C:C,Podsumowanie!A4) -> 20180 | K4: =SUMIFS('Lista uczniów_składki'!T:T,'Lista uczniów_składki'!C:C,Podsumowanie!A4) -> 10100 | L4: =K4-J4 -> -10080
A5: 3D | B5: =COUNTIFS('Lista uczniów_składki'!D:D,"Tak",'Lista uczniów_składki'!C:C,Podsumowanie!A5) -> 35 | C5: =COUNTIFS('Lista uczniów_składki'!E:E,"Tak",'Lista uczniów_składki'!C:C,Podsumowanie!A5) -> 24 | D5: =SUM(B5:C5) -> 59 | E5: 35 | F5: =IF(E5="","",H5/E5) -> 1 | G5: =H5-E5 -> 0 | H5: =COUNTIFS('Lista uczniów_składki'!D:D,"Tak",'Lista uczniów_składki'!C:C,Podsumowanie!A5)+COUNTIFS('Lista uczniów_składki'!D:D,"Nie",'Lista uczniów_składki'!C:C,Podsumowanie!A5) -> 35 | J5: =SUMIFS('Lista uczniów_składki'!U:U,'Lista uczniów_składki'!C:C,Podsumowanie!A5) -> 21530 | K5: =SUMIFS('Lista uczniów_składki'!T:T,'Lista uczniów_składki'!C:C,Podsumowanie!A5) -> 9050 | L5: =K5-J5 -> -12480
A6: 3D1 | B6: =COUNTIFS('Lista uczniów_składki'!D:D,"Tak",'Lista uczniów_składki'!C:C,Podsumowanie!A6) -> 35 | C6: =COUNTIFS('Lista uczniów_składki'!E:E,"Tak",'Lista uczniów_składki'!C:C,Podsumowanie!A6) -> 14 | D6: =SUM(B6:C6) -> 49 | E6: 36 | F6: =IF(E6="","",H6/E6) -> 1 | G6: =H6-E6 -> 0 | H6: =COUNTIFS('Lista uczniów_składki'!D:D,"Tak",'Lista uczniów_składki'!C:C,Podsumowanie!A6)+COUNTIFS('Lista uczniów_składki'!D:D,"Nie",'Lista uczniów_składki'!C:C,Podsumowanie!A6) -> 36 | J6: =SUMIFS('Lista uczniów_składki'!U:U,'Lista uczniów_składki'!C:C,Podsumowanie!A6) -> 18830 | K6: =SUMIFS('Lista uczniów_składki'!T:T,'Lista uczniów_składki'!C:C,Podsumowanie!A6) -> 10100 | L6: =K6-J6 -> -8730
A7: 3E | B7: =COUNTIFS('Lista uczniów_składki'!D:D,"Tak",'Lista uczniów_składki'!C:C,Podsumowanie!A7) -> 34 | C7: =COUNTIFS('Lista uczniów_składki'!E:E,"Tak",'Lista uczniów_składki'!C:C,Podsumowanie!A7) -> 23 | D7: =SUM(B7:C7) -> 57 | E7: 36 | F7: =IF(E7="","",H7/E7) -> 1 | G7: =H7-E7 -> 0 | H7: =COUNTIFS('Lista uczniów_składki'!D:D,"Tak",'Lista uczniów_składki'!C:C,Podsumowanie!A7)+COUNTIFS('Lista uczniów_składki'!D:D,"Nie",'Lista uczniów_składki'!C:C,Podsumowanie!A7) -> 36 | J7: =SUMIFS('Lista uczniów_składki'!U:U,'Lista uczniów_składki'!C:C,Podsumowanie!A7) -> 20830 | K7: =SUMIFS('Lista uczniów_składki'!T:T,'Lista uczniów_składki'!C:C,Podsumowanie!A7) -> 1700 | L7: =K7-J7 -> -19130
A8: 3F | B8: =COUNTIFS('Lista uczniów_składki'!D:D,"Tak",'Lista uczniów_składki'!C:C,Podsumowanie!A8) -> 26 | C8: =COUNTIFS('Lista uczniów_składki'!E:E,"Tak",'Lista uczniów_składki'!C:C,Podsumowanie!A8) -> 16 | D8: =SUM(B8:C8) -> 42 | E8: 30 | F8: =IF(E8="","",H8/E8) -> 1 | G8: =H8-E8 -> 0 | H8: =COUNTIFS('Lista uczniów_składki'!D:D,"Tak",'Lista uczniów_składki'!C:C,Podsumowanie!A8)+COUNTIFS('Lista uczniów_składki'!D:D,"Nie",'Lista uczniów_składki'!C:C,Podsumowanie!A8) -> 30 | J8: =SUMIFS('Lista uczniów_składki'!U:U,'Lista uczniów_składki'!C:C,Podsumowanie!A8) -> 15500 | K8: =SUMIFS('Lista uczniów_składki'!T:T,'Lista uczniów_składki'!C:C,Podsumowanie!A8) -> 1450 | L8: =K8-J8 -> -14050
J9: =SUM(J2:J8) -> 133530 | K9: =SUM(K2:K8) -> 45050 | L9: =SUM(L2:L8) -> -88480
A11: PODSUMOWANIE
A12: Ilość uczniów | B12: =SUM(B2:B8) -> 222 | C12: =SUM(B12:B13) -> 363
A13: Ilośc osoób towarzyszących | B13: =SUM(C2:C8) -> 141
A14: Ilość osoób rodzice + obsługa + goście | B14: =Wydatki!D4 -> 30 | C14: do ustalenia
A15: Koszt sali | B15: =SUM(Wydatki!F3:F4) -> 98010
A16: Koszty pozostałe | B16: =SUM(Wydatki!F5:F13) -> 31802.25
A17: Koszty Total | B17: =SUM(B15:B16) -> 129812.25
A19: Składka na ucznia | B19: 430 | C19: =B19+B20 -> 700
A20: Składka osoba towarzysząca | B20: =Wydatki!E3 -> 270
A22: BUDŻET | B22: =B19*B12+B20*B13 -> 133530
A23: WYDATKI | B23: =SUM(Table1[Koszt]) -> 129812.25
A24: DELTA | B24: =B22-B23 -> 3717.75
A26: KLASA | B26: Zwrot per klasa
A27: 3A | B27: =IF(B2=0,"",B$24/SUM($B$3:$B$8)*B2) -> 649.13095
A28: 3B | B28: =IF(B3=0,"",B$24/SUM($B$3:$B$8)*B3) -> 472.09524
A29: 3C | B29: =IF(B4=0,"",B$24/SUM($B$3:$B$8)*B4) -> 688.47222
A30: 3D | B30: =IF(B5=0,"",B$24/SUM($B$3:$B$8)*B5) -> 688.47222
A31: 3D1 | B31: =IF(B6=0,"",B$24/SUM($B$3:$B$8)*B6) -> 688.47222
A32: 3E | B32: =IF(B7=0,"",B$24/SUM($B$3:$B$8)*B7) -> 668.80159
A33: 3F | B33: =IF(B8=0,"",B$24/SUM($B$3:$B$8)*B8) -> 511.43651

Sheet Do wiadomości rodziców
C4: Ilość osób:
C5: Ilość osób w klasach | D5: =SUM(Podsumowanie!E2:E8) -> 233
C6: Ilość osób, które idę na studniówkę | D6: =SUM(Podsumowanie!B2:B8) -> 222
C7: Ilość osób towarzyszących | D7: =SUM(Podsumowanie!C2:C8) -> 141
C8: ilość uczniowie + osoby tow. | D8: =D6+D7 -> 363
A9: Umowa | B9: Zaliczka | C9: Ilość osób 3-cich (DJ, Foto, Goście,Rodzice) | D9: =Podsumowanie!B14 -> 30 | E9: do potwierdzenia
C11: Wydatki:
A12: TRUE | B12: TRUE | C12: Sala uczniowie (PortoFine) | D12: =Wydatki!F3 -> 98010 | E12: Zaliczka Michał Krzyszkowski
A13: TRUE | B13: TRUE | C13: Goście/pedagodzy/obsługa (PortoFine_na każde 100 osoób 10 jest za darmo na sali) | D13: =Wydatki!F4 -> 0
A14: TRUE | B14: TRUE | C14: DJ (Best Party Grupa Eventowa) | D14: =Wydatki!F5 -> 8000 | E14: Zaliczka Aneta Kanafa
A15: TRUE | B15: TRUE | C15: Fotograf (FVB) | D15: =Wydatki!F6 -> 12000 | E15: Zaliczka Michał Krzyszkowski
A16: TRUE | B16: TRUE | C16: Ścianka (Anna Muskała) | D16: =Wydatki!F7 -> 1400 | E16: Zaliczka Aneta Kanafa
A17: FALSE | B17: FALSE | C17: Opieka karetki | D17: =Wydatki!F8 -> 2000
A18: FALSE | B18: FALSE | C18: Ubezpieczenie | D18: =Wydatki!F9 -> 300
A19: FALSE | B19: FALSE | C19: Napoje gazowane [l] ->1,1l/os | D19: =Wydatki!F10 -> 3242.25
A20: FALSE | B20: FALSE | C20: Kwiaty dla Nauczycieli | D20: =Wydatki!F11 -> 840
A21: TRUE | B21: TRUE | C21: Polonez_nauka [h] (Verto) | D21: =Wydatki!F12 -> 1800 | E21: Zaliczka Aneta Kanafa
A22: FALSE | B22: FALSE | C22: Koszty dodatkowe(założyłem po 10 zł/os na nieprzewidziane wydatki) | D22: =Wydatki!F13 -> 2220
C23: Total | D23: =Wydatki!F14 -> 129812.25
C26: Składka:
C27: Składka per uczeń | D27: =Podsumowanie!B19 -> 430 | E27: =SUM(D27:D28) -> 700
C28: Składka per osoba towarzysząca | D28: =Podsumowanie!B20 -> 270
C31: Składki_status per klasa:
C32: Klasa | D32: Winno być | E32: Zebrane | F32: Delta
C33: 3A | D33: =SUMIFS('Lista uczniów_składki'!U:U,'Lista uczniów_składki'!C:C,'Do wiadomości rodziców'!C33) -> 22020 | E33: =SUMIFS('Lista uczniów_składki'!T:T,'Lista uczniów_składki'!C:C,'Do wiadomości rodziców'!C33) -> 7350 | F33: =E33-D33 -> -14670
C34: 3B | D34: =SUMIFS('Lista uczniów_składki'!U:U,'Lista uczniów_składki'!C:C,'Do wiadomości rodziców'!C34) -> 14640 | E34: =SUMIFS('Lista uczniów_składki'!T:T,'Lista uczniów_składki'!C:C,'Do wiadomości rodziców'!C34) -> 5300 | F34: =E34-D34 -> -9340
C35: 3C | D35: =SUMIFS('Lista uczniów_składki'!U:U,'Lista uczniów_składki'!C:C,'Do wiadomości rodziców'!C35) -> 20180 | E35: =SUMIFS('Lista uczniów_składki'!T:T,'Lista uczniów_składki'!C:C,'Do wiadomości rodziców'!C35) -> 10100 | F35: =E35-D35 -> -10080
C36: 3D | D36: =SUMIFS('Lista uczniów_składki'!U:U,'Lista uczniów_składki'!C:C,'Do wiadomości rodziców'!C36) -> 21530 | E36: =SUMIFS('Lista uczniów_składki'!T:T,'Lista uczniów_składki'!C:C,'Do wiadomości rodziców'!C36) -> 9050 | F36: =E36-D36 -> -12480
C37: 3D1 | D37: =SUMIFS('Lista uczniów_składki'!U:U,'Lista uczniów_składki'!C:C,'Do wiadomości rodziców'!C37) -> 18830 | E37: =SUMIFS('Lista uczniów_składki'!T:T,'Lista uczniów_składki'!C:C,'Do wiadomości rodziców'!C37) -> 10100 | F37: =E37-D37 -> -8730
C38: 3E | D38: =SUMIFS('Lista uczniów_składki'!U:U,'Lista uczniów_składki'!C:C,'Do wiadomości rodziców'!C38) -> 20830 | E38: =SUMIFS('Lista uczniów_składki'!T:T,'Lista uczniów_składki'!C:C,'Do wiadomości rodziców'!C38) -> 1700 | F38: =E38-D38 -> -19130
C39: 3F | D39: =SUMIFS('Lista uczniów_składki'!U:U,'Lista uczniów_składki'!C:C,'Do wiadomości rodziców'!C39) -> 15500 | E39: =SUMIFS('Lista uczniów_składki'!T:T,'Lista uczniów_składki'!C:C,'Do wiadomości rodziców'!C39) -> 1450 | F39: =E39-D39 -> -14050
C40: Total | D40: =SUBTOTAL(109,D33:D39) -> 133530 | E40: =SUBTOTAL(109,E33:E39) -> 45050 | F40: =SUBTOTAL(109,Table5[Delta]) -> -88480
C44: Środki u rodziców: | F44: =SUM(F46:F52) -> 14420
C45: Osoba | D45: Kwota | E45: Zaliczki | F45: Pozostaje
C46: Michał Krzyszkowski | D46: 5750 | E46: -4000 | F46: =SUM(D46:E46) -> 1750
C47: Aneta Kanafa | D47: 7350 | E47: -680 | F47: =SUM(D47:E47) -> 6670
C48: P. Katarzyna 4D1 | D48: 6000 | E48: 0 | F48: =SUM(D48:E48) -> 6000

Sheet Zadania
A1: Zadanie | B1: Kiedy? | C1: Kto? | D1: Wykonane?
A2: Nauka poloneza - kontakt | B2: 46275 | C2: Katarzyna 3D1 | D2: TRUE
A3: Potwierdzenie ilości osób do PortoFine | B3: 46401 | C3: Michał Krzyszkowski | D3: FALSE
A4: Potwierdzenie ilości osób wewnętrznie | B4: 46395 | C4: Michał Krzyszkowski | D4: FALSE
A5: Zakup kasetki na pieniądze | B5: 46254 | C5: Michał Krzyszkowski | D5: FALSE
A6: Zakup napojów gazowanych | B6: 46412 | C6: Do ustalenia | D6: FALSE
A7: Listy wpłat/wypłat_template | B7: 46185 | C7: Michał Krzyszkowski | D7: TRUE
A8: Zasady wpłat/wypłat | B8: 46192 | C8: Michał Krzyszkowski | D8: TRUE
A9: Ustalenie osób upoważnionych | B9: 46192 | C9: Cała grupa | D9: FALSE
A10: Zawiązanie komitetu | B10: 46267 | C10: Cała grupa | D10: FALSE
A11: Zaproszenie gości | B11: 46356 | C11: Uczniowie | D11: FALSE
D12: FALSE
D13: FALSE
D14: FALSE
D15: FALSE
D16: FALSE
D17: FALSE
D18: FALSE
D19: FALSE
D20: FALSE

Sheet Notes
B3: u mnie | C3: 5750 | D3: 3B->3C->3D1->część 3F
B4: Paulina Drozdek | C4: 500 | D4: 3F-resztka(500 zł)

Sheet Dashboard
AC5: Wydatki
AC6: Opis | AD6: Koszt | AE6: Zaliczka | AF6: Pozostało | AG6: Komentarz | AN6: KLASA | AO6: Zwrot per klasa
A7: Typ uczestnika | B7: Wysokosc skladki | H7: KLASA | I7: # UCZNIÓW (którzy idą) | J7: # OS. Tow. | K7: Składki_winno być | L7: Składki zebrane | M7: Delta | P7: ='Do wiadomości rodziców'!C31 -> Składki_status per klasa: | AC7: =Wydatki!A3 -> Sala uczniowie(PortoFine) | AD7: =Wydatki!F3 -> 98010 | AE7: =Wydatki!G3 -> 2000 | AF7: =Wydatki!H3 -> 96010 | AG7: =Wydatki!I3 -> Zaliczka Michał Krzyszkowski | AN7: =Podsumowanie!A27 -> 3A | AO7: =Podsumowanie!B27 -> 649.13095
A8: =Podsumowanie!A19 -> Składka na ucznia | B8: =Podsumowanie!B19 -> 430 | H8: =Podsumowanie!A2 -> 3A | I8: =Podsumowanie!B2 -> 33 | J8: =Podsumowanie!C2 -> 29 | K8: =Podsumowanie!J2 -> 22020 | L8: =Podsumowanie!K2 -> 7350 | M8: =Podsumowanie!L2 -> -14670 | P8: Klasa | Q8: Winno być | R8: Zebrane | S8: Delta | X8: Kolumna1 | Y8: Kolumna2 | AC8: =Wydatki!A4 -> Goście/pedagodzy/obsługa (PortoFine_na każde 100 osoób 10 jest za darmo na sali) | AD8: =Wydatki!F4 -> 0 | AE8: =Wydatki!G4 -> 0 | AF8: =Wydatki!H4 -> 0 | AG8: =Wydatki!I4 -> 0 | AN8: =Podsumowanie!A28 -> 3B | AO8: =Podsumowanie!B28 -> 472.09524
A9: =Podsumowanie!A20 -> Składka osoba towarzysząca | B9: =Podsumowanie!B20 -> 270 | H9: =Podsumowanie!A3 -> 3B | I9: =Podsumowanie!B3 -> 24 | J9: =Podsumowanie!C3 -> 16 | K9: =Podsumowanie!J3 -> 14640 | L9: =Podsumowanie!K3 -> 5300 | M9: =Podsumowanie!L3 -> -9340 | P9: ='Do wiadomości rodziców'!C33 -> 3A | Q9: ='Do wiadomości rodziców'!D33 -> 22020 | R9: ='Do wiadomości rodziców'!E33 -> 7350 | S9: ='Do wiadomości rodziców'!F33 -> -14670 | X9: ='Do wiadomości rodziców'!C6 -> Ilość osób, które idę na studniówkę | Y9: ='Do wiadomości rodziców'!D6 -> 222 | AC9: =Wydatki!A5 -> DJ (Best Party Grupa Eventowa) | AD9: =Wydatki!F5 -> 8000 | AE9: =Wydatki!G5 -> 400 | AF9: =Wydatki!H5 -> 7600 | AG9: =Wydatki!I5 -> Zaliczka Aneta Kanafa | AN9: =Podsumowanie!A29 -> 3C | AO9: =Podsumowanie!B29 -> 688.47222
H10: =Podsumowanie!A4 -> 3C | I10: =Podsumowanie!B4 -> 35 | J10: =Podsumowanie!C4 -> 19 | K10: =Podsumowanie!J4 -> 20180 | L10: =Podsumowanie!K4 -> 10100 | M10: =Podsumowanie!L4 -> -10080 | P10: ='Do wiadomości rodziców'!C34 -> 3B | Q10: ='Do wiadomości rodziców'!D34 -> 14640 | R10: ='Do wiadomości rodziców'!E34 -> 5300 | S10: ='Do wiadomości rodziców'!F34 -> -9340 | X10: ='Do wiadomości rodziców'!C7 -> Ilość osób towarzyszących | Y10: ='Do wiadomości rodziców'!D7 -> 141 | AC10: =Wydatki!A6 -> Fotograf(FVB) | AD10: =Wydatki!F6 -> 12000 | AE10: =Wydatki!G6 -> 2000 | AF10: =Wydatki!H6 -> 10000 | AG10: =Wydatki!I6 -> Zaliczka Michał Krzyszkowski | AN10: =Podsumowanie!A30 -> 3D | AO10: =Podsumowanie!B30 -> 688.47222
H11: =Podsumowanie!A5 -> 3D | I11: =Podsumowanie!B5 -> 35 | J11: =Podsumowanie!C5 -> 24 | K11: =Podsumowanie!J5 -> 21530 | L11: =Podsumowanie!K5 -> 9050 | M11: =Podsumowanie!L5 -> -12480 | P11: ='Do wiadomości rodziców'!C35 -> 3C | Q11: ='Do wiadomości rodziców'!D35 -> 20180 | R11: ='Do wiadomości rodziców'!E35 -> 10100 | S11: ='Do wiadomości rodziców'!F35 -> -10080 | X11: ='Do wiadomości rodziców'!C9 -> Ilość osób 3-cich (DJ, Foto, Goście,Rodzice) | Y11: ='Do wiadomości rodziców'!D9 -> 30 | AC11: =Wydatki!A7 -> Ścianka(Anna Muskała) | AD11: =Wydatki!F7 -> 1400 | AE11: =Wydatki!G7 -> 100 | AF11: =Wydatki!H7 -> 1300 | AG11: =Wydatki!I7 -> Zaliczka Aneta Kanafa | AN11: =Podsumowanie!A31 -> 3D1 | AO11: =Podsumowanie!B31 -> 688.47222
H12: =Podsumowanie!A6 -> 3D1 | I12: =Podsumowanie!B6 -> 35 | J12: =Podsumowanie!C6 -> 14 | K12: =Podsumowanie!J6 -> 18830 | L12: =Podsumowanie!K6 -> 10100 | M12: =Podsumowanie!L6 -> -8730 | P12: ='Do wiadomości rodziców'!C36 -> 3D | Q12: ='Do wiadomości rodziców'!D36 -> 21530 | R12: ='Do wiadomości rodziców'!E36 -> 9050 | S12: ='Do wiadomości rodziców'!F36 -> -12480 | AC12: =Wydatki!A8 -> Opieka karetki | AD12: =Wydatki!F8 -> 2000 | AE12: =Wydatki!G8 -> 0 | AF12: =Wydatki!H8 -> 2000 | AG12: =Wydatki!I8 -> 0 | AN12: =Podsumowanie!A32 -> 3E | AO12: =Podsumowanie!B32 -> 668.80159
H13: =Podsumowanie!A7 -> 3E | I13: =Podsumowanie!B7 -> 34 | J13: =Podsumowanie!C7 -> 23 | K13: =Podsumowanie!J7 -> 20830 | L13: =Podsumowanie!K7 -> 1700 | M13: =Podsumowanie!L7 -> -19130 | P13: ='Do wiadomości rodziców'!C37 -> 3D1 | Q13: ='Do wiadomości rodziców'!D37 -> 18830 | R13: ='Do wiadomości rodziców'!E37 -> 10100 | S13: ='Do wiadomości rodziców'!F37 -> -8730 | AC13: =Wydatki!A9 -> Ubezpieczenie | AD13: =Wydatki!F9 -> 300 | AE13: =Wydatki!G9 -> 0 | AF13: =Wydatki!H9 -> 300 | AG13: =Wydatki!I9 -> 0 | AN13: =Podsumowanie!A33 -> 3F | AO13: =Podsumowanie!B33 -> 511.43651
H14: =Podsumowanie!A8 -> 3F | I14: =Podsumowanie!B8 -> 26 | J14: =Podsumowanie!C8 -> 16 | K14: =Podsumowanie!J8 -> 15500 | L14: =Podsumowanie!K8 -> 1450 | M14: =Podsumowanie!L8 -> -14050 | P14: ='Do wiadomości rodziców'!C38 -> 3E | Q14: ='Do wiadomości rodziców'!D38 -> 20830 | R14: ='Do wiadomości rodziców'!E38 -> 1700 | S14: ='Do wiadomości rodziców'!F38 -> -19130 | AC14: =Wydatki!A10 -> Napoje gazowane [l] ->1,1l/os | AD14: =Wydatki!F10 -> 3242.25 | AE14: =Wydatki!G10 -> 0 | AF14: =Wydatki!H10 -> 3242.25 | AG14: =Wydatki!I10 -> 0
P15: ='Do wiadomości rodziców'!C39 -> 3F | Q15: ='Do wiadomości rodziców'!D39 -> 15500 | R15: ='Do wiadomości rodziców'!E39 -> 1450 | S15: ='Do wiadomości rodziców'!F39 -> -14050 | AC15: =Wydatki!A11 -> Kwiaty dla Nauczycieli | AD15: =Wydatki!F11 -> 840 | AE15: =Wydatki!G11 -> 0 | AF15: =Wydatki!H11 -> 840 | AG15: =Wydatki!I11 -> 0
P16: ='Do wiadomości rodziców'!C40 -> Total | Q16: ='Do wiadomości rodziców'!D40 -> 133530 | R16: ='Do wiadomości rodziców'!E40 -> 45050 | S16: ='Do wiadomości rodziców'!F40 -> -88480 | AC16: =Wydatki!A12 -> Polonez_nauka [h] (Verto) | AD16: =Wydatki!F12 -> 1800 | AE16: =Wydatki!G12 -> 180 | AF16: =Wydatki!H12 -> 1620 | AG16: =Wydatki!I12 -> Zaliczka Aneta Kanafa
AC17: =Wydatki!A13 -> Koszty dodatkowe | AD17: =Wydatki!F13 -> 2220 | AE17: =Wydatki!G13 -> 75.85 | AF17: =Wydatki!H13 -> 2144.15 | AG17: =Wydatki!I13 -> zakup Kasetki na pieniądze 75.85 (zapłacone)-> Zaiks i inne 1100 zł(do opłacenia)
AD18: =Wydatki!F14 -> 129812.25 | AE18: =Wydatki!G14 -> 4755.85 | AF18: =Wydatki!H14 -> 125056.4

Sheet Ankieta#1_13.04.26
A1: ID | B1: Godzina rozpoczęcia | C1: Godzina ukończenia | D1: Adres e-mail | E1: Imię | F1: Nazwisko | G1: Klasa | H1: Czy będziesz uczestniczył/uczestniczyła w Studniówce? | I1: Czy idziesz z osobą towarzyszącą?
A2: 1 | B2: 46125.645 | C2: 46125.646 | D2: anonimowe | E2: Daria | F2: Rząsowska | G2: 3E | H2: Tak | I2: Tak | K2: =F2&E2 -> RząsowskaDaria | M2: =COUNTIF($K$2:$K$266,K2) -> 1
A3: =A2+1 -> 2 | B3: 46125.647 | C3: 46125.647 | D3: anonimowe | E3: Martyna | F3: Szwejda | G3: 3E | H3: Tak | I3: Tak | K3: =F3&E3 -> SzwejdaMartyna | M3: =COUNTIF($K$2:$K$266,K3) -> 1
A4: =A3+1 -> 3 | B4: 46125.649 | C4: 46125.649 | D4: anonimowe | E4: Mikołaj | F4: Surosz | G4: 3D1 | H4: Tak | I4: Nie | K4: =F4&E4 -> SuroszMikołaj | M4: =COUNTIF($K$2:$K$266,K4) -> 1
A5: =A4+1 -> 4 | B5: 46125.65 | C5: 46125.65 | D5: anonimowe | E5: Aleksandra | F5: Hofman | G5: 3E | H5: Tak | I5: Tak | K5: =F5&E5 -> HofmanAleksandra | M5: =COUNTIF($K$2:$K$266,K5) -> 1
A6: =A5+1 -> 5 | B6: 46125.652 | C6: 46125.653 | D6: anonimowe | E6: Patrycja | F6: Dworak | G6: 3E | H6: Tak | I6: Tak | K6: =F6&E6 -> DworakPatrycja | M6: =COUNTIF($K$2:$K$266,K6) -> 1
A7: =A6+1 -> 6 | B7: 46125.658 | C7: 46125.658 | D7: anonimowe | E7: Lena | F7: Krzyszkowska | G7: 3D1 | H7: Tak | I7: Tak | K7: =F7&E7 -> KrzyszkowskaLena | M7: =COUNTIF($K$2:$K$266,K7) -> 1
A8: =A7+1 -> 7 | B8: 46125.67 | C8: 46125.671 | D8: anonimowe | E8: Aleksandra | F8: Alama | G8: 3E | H8: Tak | I8: Tak | K8: =F8&E8 -> AlamaAleksandra | M8: =COUNTIF($K$2:$K$266,K8) -> 1
A9: =A8+1 -> 8 | B9: 46125.677 | C9: 46125.677 | D9: anonimowe | E9: Alan | F9: Półrola | G9: 3D1 | H9: Tak | I9: Nie | K9: =F9&E9 -> PółrolaAlan | M9: =COUNTIF($K$2:$K$266,K9) -> 1
A10: =A9+1 -> 9 | B10: 46125.683 | C10: 46125.683 | D10: anonimowe | E10: Jakub | F10: Berski | G10: 3D1 | H10: Tak | I10: Tak | K10: =F10&E10 -> BerskiJakub | M10: =COUNTIF($K$2:$K$266,K10) -> 1
A11: =A10+1 -> 10 | B11: 46125.697 | C11: 46125.697 | D11: anonimowe | E11: Weronika | F11: Ciupa | G11: 3E | H11: Tak | I11: Tak | K11: =F11&E11 -> CiupaWeronika | M11: =COUNTIF($K$2:$K$266,K11) -> 1
A12: =A11+1 -> 11 | B12: 46125.702 | C12: 46125.702 | D12: anonimowe | E12: Zofia | F12: Zawalska | G12: 3D1 | H12: Tak | I12: Nie | K12: =F12&E12 -> ZawalskaZofia | M12: =COUNTIF($K$2:$K$266,K12) -> 1
A13: =A12+1 -> 12 | B13: 46125.722 | C13: 46125.722 | D13: anonimowe | E13: Roksana | F13: Rosik | G13: 3E | H13: Tak | I13: Tak | K13: =F13&E13 -> RosikRoksana | M13: =COUNTIF($K$2:$K$266,K13) -> 1
A14: =A13+1 -> 13 | B14: 46125.762 | C14: 46125.762 | D14: anonimowe | E14: Wiktoria | F14: Warda | G14: 3B | H14: Tak | I14: Tak | K14: =F14&E14 -> WardaWiktoria | M14: =COUNTIF($K$2:$K$266,K14) -> 1
... A234: =A233+1 -> 233 | B234: 46175.877 | C234: 46175.877 | D234: anonimowe | E234: Jan | F234: Domański | G234: 3E | H234: Nie | I234: Nie | K234: =F234&E234 -> DomańskiJan | M234: =COUNTIF($K$2:$K$266,K234) -> 1
